<?xml version="1.0" encoding="utf-8" ?>
<!-- <include file="$(find tangs_description)/urdf/tangs.gazebo"/> -->
<!-- Solução para o problema do braço ficar tremendo no início -->
<!-- https://robotics.stackexchange.com/questions/58995/manipulator-shakes-wobbles/58996#58996 -->
<robot name="tangs">
    <link name="world" />
    <joint name="base_joint" type="fixed">
        <parent link="world" />
        <child link="link_base" />
        <origin rpy="0 0 0" xyz="0.0 0 0.0" />
    </joint>
    <link name="link_base">
        <visual>
            <origin rpy="0 0 0" xyz="0 0 0" />
            <geometry>
                <mesh filename="package://tangs_description/models/thangs3/link_base.stl" />
            </geometry>
            <material name="Gazebo/Grey" />
        </visual>
        <inertial>
            <origin rpy="0 0 0" xyz="0 0 -0.30" />
            <mass value="0.620" />
            <inertia ixx="0.010581333333333333" ixy="0" ixz="0" iyy="0.010581333333333333" iyz="0" izz="0.010581333333333333" />
        </inertial>
        <collision>
            <origin rpy="0 0 0" xyz="0 0 0.03" />
            <geometry>
                <!-- <mesh filename="package://tangs_description/models/thangs3/link_base.stl"/> -->
                <box size="0.12 0.12 0.06" />
            </geometry>
        </collision>
    </link>
    <link name="link_body">
        <visual>
            <origin rpy="0 0 0" xyz="0 0 0" />
            <geometry>
                <mesh filename="package://tangs_description/models/thangs3/link_body.stl" />
            </geometry>
            <material name="Gazebo/Grey" />
        </visual>
        <collision>
            <origin rpy="0 0 0" xyz="0 0 0" />
            <geometry>
                <!-- <cylinder radius="0.050" length="0.067" /> -->
                <mesh filename="package://tangs_description/models/thangs3/link_body.stl" />
            </geometry>
        </collision>
        <inertial>
            <origin rpy="0 0 0" xyz="-6.44e-03 1.36e-03 1.73e-02" />
            <mass value="8.50e-02" />
            <inertia ixx="0.002" ixy="0.0" ixz="0.0" iyy="0.02" iyz="0.0" izz="0.002" />
        </inertial>
    </link>
    <joint name="waist" type="revolute">
        <origin rpy="0 0 1.55" xyz="0 0 5.60e-02" />
        <parent link="link_base" />
        <child link="link_body" />
        <axis xyz="0 0 1" />
        <limit effort="300" lower="-1.570796327" upper="1.570796327" velocity="3" />
        <joint_properties friction="0.0" />
    </joint>
    <transmission name="tran1">
        <type>transmission_interface/SimpleTransmission</type>
        <joint name="waist">
            <hardwareInterface>hardware_interface/PositionJointInterface</hardwareInterface>
        </joint>
        <actuator name="motor1">
            <hardwareInterface>hardware_interface/PositionJointInterface</hardwareInterface>
            <mechanicalReduction>1</mechanicalReduction>
        </actuator>
    </transmission>
    <link name="link_arm">
        <visual>
            <origin rpy="3.141592654 0 -1.570796327" xyz="-5.77e-02 6.02e-04 0" />
            <geometry>
                <mesh filename="package://tangs_description/models/thangs3/link_arm.stl" />
            </geometry>
            <material name="Gazebo/Grey" />
        </visual>
        <collision>
            <origin rpy="3.141592654 0 -1.570796327" xyz="-5.77e-02 6.02e-04 0" />
            <geometry>
                <mesh filename="package://tangs_description/models/thangs3/link_arm.stl" />
            </geometry>
        </collision>
        <inertial>
            <origin rpy="0 0 0" xyz="-5.92e-02 0 -7.79e-03" />
            <mass value="8.50e-03" />
            <inertia ixx="0.002" ixy="0.0" ixz="0.0" iyy="0.02" iyz="0.0" izz="0.002" />
        </inertial>
    </link>
    <joint name="shoulder" type="revolute">
        <origin rpy="1.570796327 1.570796327 -1.570796327" xyz="-4.00e-03 1.40e-02 4.03e-02" />
        <parent link="link_body" />
        <child link="link_arm" />
        <axis xyz="0 0 1" />
        <limit effort="200" lower="-1.570796327" upper="1.570796327" velocity="3" />
        <joint_properties friction="0.0" />
    </joint>
    <transmission name="tran2">
        <type>transmission_interface/SimpleTransmission</type>
        <joint name="shoulder">
            <hardwareInterface>hardware_interface/PositionJointInterface</hardwareInterface>
        </joint>
        <actuator name="motor2">
            <hardwareInterface>hardware_interface/PositionJointInterface</hardwareInterface>
            <mechanicalReduction>1</mechanicalReduction>
        </actuator>
    </transmission>
    <link name="link_forearm">
        <visual>
            <origin rpy="-3.141592654 0 0" xyz="0 -3.22e-02 6.00e-03" />
            <geometry>
                <mesh filename="package://tangs_description/models/thangs3/link_forearm.stl" />
            </geometry>
            <material name="Gazebo/Grey" />
        </visual>
        <collision>
            <origin rpy="-3.141592654 0 0" xyz="0 -3.22e-02 6.00e-03" />
            <geometry>
                <mesh filename="package://tangs_description/models/thangs3/link_forearm.stl" />
            </geometry>
        </collision>
        <inertial>
            <origin rpy="0 0 0" xyz="0 -3.93e-02 -7.40e-03" />
            <mass value="5.28e-03" />
            <inertia ixx="0.002" ixy="0.0" ixz="0.0" iyy="0.02" iyz="0.0" izz="0.002" />
        </inertial>
    </link>
    <joint name="elbow" type="revolute">
        <origin rpy="3.141592654 0 6.09e-01" xyz="-1.20e-01 0 0" />
        <parent link="link_arm" />
        <child link="link_forearm" />
        <axis xyz="0 0 1" />
        <limit effort="200" lower="-2.5" upper="0.6" velocity="3" />
        <joint_properties friction="0.0" />
    </joint>
    <transmission name="tran3">
        <type>transmission_interface/SimpleTransmission</type>
        <joint name="elbow">
            <hardwareInterface>hardware_interface/PositionJointInterface</hardwareInterface>
        </joint>
        <actuator name="motor3">
            <hardwareInterface>hardware_interface/PositionJointInterface</hardwareInterface>
            <mechanicalReduction>1</mechanicalReduction>
        </actuator>
    </transmission>
    <link name="link_hand">
        <visual>
            <origin rpy="-1.570796327 0 0" xyz="4.99e-03 -1.40e-02 -2.30e-02" />
            <geometry>
                <mesh filename="package://tangs_description/models/thangs3/link_hand.stl" />
            </geometry>
            <material name="Gazebo/Grey" />
        </visual>
        <collision>
            <origin rpy="-1.570796327 0 0" xyz="4.99e-03 -1.40e-02 -2.30e-02" />
            <geometry>
                <mesh filename="package://tangs_description/models/thangs3/link_hand.stl" />
            </geometry>
        </collision>
        <inertial>
            <origin rpy="0 0 0" xyz="5.03e-03 -6.14e-03 -1.77e-02" />
            <mass value="1.83e-03" />
            <inertia ixx="0.002" ixy="0.0" ixz="0.0" iyy="0.02" iyz="0.0" izz="0.002" />
        </inertial>
    </link>
    <joint name="wrist_yaw" type="revolute">
        <origin rpy="-1.570796327 0 0" xyz="-5.31e-03 -8.97e-02 -7.51e-03" />
        <parent link="link_forearm" />
        <child link="link_hand" />
        <axis xyz="0 0 1" />
        <limit effort="200" lower="-1.570796327" upper="1.570796327" velocity="3" />
        <joint_properties friction="0.0" />
    </joint>
    <transmission name="tran4">
        <type>transmission_interface/SimpleTransmission</type>
        <joint name="wrist_yaw">
            <hardwareInterface>hardware_interface/PositionJointInterface</hardwareInterface>
        </joint>
        <actuator name="motor4">
            <hardwareInterface>hardware_interface/PositionJointInterface</hardwareInterface>
            <mechanicalReduction>1</mechanicalReduction>
        </actuator>
    </transmission>
    <link name="palm_link">
        <collision>
            <origin rpy="3.141592654 -3.141592654 0.0" xyz="0.015 0.015 -0.018" />
            <geometry>
                <!-- <mesh filename="package://gripper_description/meshes/collision/RG3_Palm_col.stl"/> -->
                <mesh filename="package://gripper_description/meshes/visual/RG3_gripper_base_m_tk2.stl" />
            </geometry>
        </collision>
        <visual>
            <!-- <origin xyz="0.00 0.0015 -0.014" rpy="0.00 0.00 0.00"/> -->
            <origin rpy="3.141592654 -3.141592654 0.0" xyz="0.015 0.015 -0.018" />
            <geometry>
                <mesh filename="package://gripper_description/meshes/visual/RG3_gripper_base_m_tk2.stl" />
            </geometry>
            <material name="Gazebo/Grey" />
        </visual>
        <inertial>
            <origin rpy="0.00 0.00 0.00" xyz="-0.061902 0.000129 -0.000005" />
            <mass value="0.02" />
            <inertia ixx="0.002" ixy="0.0" ixz="0.0" iyy="0.02" iyz="0.0" izz="0.002" />
            <!-- <inertia ixx="0.000862" ixy="0.000000" ixz="0.000000"
                     iyy="0.002401" iyz="-0.000001"
                     izz="0.002620" /> -->
        </inertial>
    </link>
    <joint name="wrist_pitch" type="revolute">
        <origin rpy="0 -3.81e-02 0" xyz="0.00 -1.40e-02 -2.80e-02" />
        <parent link="link_hand" />
        <child link="palm_link" />
        <!-- Nome do link inicial do gripper-->
        <axis xyz="0 1 0" />
        <limit effort="200" lower="-3.141592654" upper="0" velocity="3" />
        <joint_properties friction="0.0" />
    </joint>
    <transmission name="tran5">
        <type>transmission_interface/SimpleTransmission</type>
        <joint name="wrist_pitch">
            <hardwareInterface>hardware_interface/PositionJointInterface</hardwareInterface>
        </joint>
        <actuator name="wrist_pitch_motor">
            <hardwareInterface>hardware_interface/PositionJointInterface</hardwareInterface>
            <mechanicalReduction>1</mechanicalReduction>
        </actuator>
    </transmission>
    <link name="l_moment_arm_link">
        <collision>
            <origin rpy="0.00 0.00 3.01415" xyz="0.01 -0.0021 0.0005" />
            <geometry>
                <!-- <mesh filename="package://gripper_description/meshes/collision/RG3_GearLeft_col.stl"/> -->
                <mesh filename="package://gripper_description/meshes/visual/RG3_gear_left_m.stl" />
            </geometry>
        </collision>
        <visual>
            <origin rpy="0.00 0.00 3.01415" xyz="0.01 -0.0021 0.0005" />
            <geometry>
                <mesh filename="package://gripper_description/meshes/visual/RG3_gear_left_m.stl" />
            </geometry>
        </visual>
        <inertial>
            <origin rpy="0.00 0.00 0.00" xyz="0.017004 0.006397 -0.010300" />
            <mass value="0.0060209" />
            <inertia ixx="0.002" ixy="0.0" ixz="0.0" iyy="0.02" iyz="0.0" izz="0.002" />
        </inertial>
    </link>
    <joint name="gripper_joint" type="revolute">
        <parent link="palm_link" />
        <child link="l_moment_arm_link" />
        <origin rpy="0 0 3.141592654" xyz="-0.042 -0.005 0.012" />
        <axis xyz="0 0 1" />
        <limit effort="200" lower="0" upper="1.570796327" velocity="3" />
        <dynamics damping="0.3" friction="0.0" />
        <implicitSpringDamper>True</implicitSpringDamper>
    </joint>
    <transmission name="gripper_joint_tran">
        <type>transmission_interface/SimpleTransmission</type>
        <joint name="gripper_joint">
            <hardwareInterface>hardware_interface/PositionJointInterface</hardwareInterface>
        </joint>
        <actuator name="gripper_joint_motor">
            <hardwareInterface>hardware_interface/PositionJointInterface</hardwareInterface>
            <mechanicalReduction>1</mechanicalReduction>
        </actuator>
    </transmission>
    <link name="r_moment_arm_link">
        <collision>
            <origin rpy="0.00 0.00 3.000415" xyz="0.01 -0.0111 0.0005" />
            <geometry>
                <mesh filename="package://gripper_description/meshes/visual/RG3_gear_right_m.stl" />
            </geometry>
        </collision>
        <visual>
            <origin rpy="0.00 0.00 3.000415" xyz="0.01 -0.0111 0.0005" />
            <geometry>
                <mesh filename="package://gripper_description/meshes/visual/RG3_gear_right_m.stl" />
            </geometry>
        </visual>
        <inertial>
            <origin rpy="0.00 0.00 0.00" xyz="0.017004 -0.006397 -0.010300" />
            <mass value="0.0060209" />
            <inertia ixx="0.002" ixy="0.0" ixz="0.0" iyy="0.02" iyz="0.0" izz="0.002" />
        </inertial>
    </link>
    <joint name="r_finger_1_joint" type="revolute">
        <parent link="palm_link" />
        <child link="r_moment_arm_link" />
        <origin rpy="0 0 3.141592654" xyz="-0.042 0.022 0.008" />
        <axis xyz="0 0 1" />
        <limit effort="10.6" lower="-1.570796327" upper="1.570796327" velocity="3.14" />
        <mimic joint="gripper_joint" multiplier="-1" />
        <dynamics damping="0.3" friction="0.0" />
        <implicitSpringDamper>True</implicitSpringDamper>
    </joint>
    
    <link name="l_finger_link">
        <collision>
            <origin rpy="0.00 0.00 -0.38" xyz="0.030 -0.005 0.0045" />
            <geometry>
                <!-- <mesh filename="package://gripper_description/meshes/collision/RG3_griplink_left_col.stl"/> -->
                <mesh filename="package://gripper_description/meshes/visual/RG3_grip_finger_left_m.stl" />
            </geometry>
        </collision>
        <visual>
            <origin rpy="0.00 0.00 -0.38" xyz="0.030 -0.005 0.0045" />
            <geometry>
                <mesh filename="package://gripper_description/meshes/visual/RG3_grip_finger_left_m.stl" />
            </geometry>
        </visual>
        <inertial>
            <origin rpy="0.00 0.00 0.00" xyz="0.024695 -0.010178 -0.010001" />
            <mass value="0.0081638" />
            <inertia ixx="0.002" ixy="0.0" ixz="0.0" iyy="0.02" iyz="0.0" izz="0.002" />
        </inertial>
    </link>
    <joint name="l_finger_2_joint" type="revolute">
        <parent link="l_moment_arm_link" />
        <child link="l_finger_link" />
        <origin rpy="0 0 0" xyz="0.0315 0.0008 0.000" />
        <axis xyz="0 0 1" />
        <limit effort="10.6" lower="-1.570796327" upper="1.570796327" velocity="3" />
        <mimic joint="gripper_joint" multiplier="-1" />
        <dynamics damping="0.3" friction="0.0" />
        <implicitSpringDamper>True</implicitSpringDamper>
    </joint>
    <transmission name="l_finger_2_joint_tran">
        <type>transmission_interface/SimpleTransmission</type>
        <joint name="l_finger_2_joint">
            <hardwareInterface>hardware_interface/PositionJointInterface</hardwareInterface>
        </joint>
        <actuator name="l_finger_2_joint_motor">
            <hardwareInterface>hardware_interface/PositionJointInterface</hardwareInterface>
            <mechanicalReduction>1</mechanicalReduction>
        </actuator>
    </transmission>
    <link name="r_finger_link">
        <collision>
            <origin rpy="0.00 3.1415 0.38" xyz="0.022 0.026 0.020" />
            <geometry>
                <mesh filename="package://gripper_description/meshes/visual/gear_right3.stl" />
            </geometry>
        </collision>
        <visual>
            <origin rpy="0.00 3.1415 0.38" xyz="0.022 0.026 0.020" />
            <geometry>
                <mesh filename="package://gripper_description/meshes/visual/gear_right3.stl" />
            </geometry>
        </visual>
        <inertial>
            <origin rpy="0.00 0.00 0.00" xyz="0.024695 0.010178 -0.010000" />
            <mass value="0.0081637" />
            <inertia ixx="0.002" ixy="0.0" ixz="0.0" iyy="0.02" iyz="0.0" izz="0.002" />
        </inertial>
    </link>
    <joint name="r_finger_2_joint" type="revolute">
        <parent link="r_moment_arm_link" />
        <child link="r_finger_link" />
        <origin rpy="0 0 0" xyz="0.032 -0.0015 0.005" />
        <axis xyz="0 0 1" />
        <limit effort="10.6" lower="-1.570796327" upper="1.570796327" velocity="3.0" />
        <mimic joint="gripper_joint" multiplier="1" />
        <dynamics damping="0.3" friction="0.0" />   
    </joint>

    <link name="l_truss_arm_link">
        <collision>
            <origin rpy="0.00 0.00 0" xyz="0.016 0.00 0.00" />
            <geometry>
                <!-- <mesh filename="package://gripper_description/meshes/collision/RG3_griplink_left_col.stl"/> -->
                <mesh filename="package://gripper_description/meshes/visual/RG3_grip_link_left_m.stl" />
            </geometry>
        </collision>
        <visual>
            <origin rpy="0.00 0.00 0" xyz="0.016 0.00 0.00" />
            <geometry>
                <mesh filename="package://gripper_description/meshes/visual/RG3_grip_link_left_m.stl" />
            </geometry>
        </visual>
        <inertial>
            <origin rpy="0.00 0.00 0.00" xyz="0.023075 0.012136 -0.010000" />
            <mass value="0.0065927" />
            <inertia ixx="0.002" ixy="0.0" ixz="0.0" iyy="0.02" iyz="0.0" izz="0.002" />
        </inertial>
    </link>
    <joint name="l_finger_passive_joint" type="revolute">
        <parent link="palm_link" />
        <child link="l_truss_arm_link" />
        <origin rpy="0 0 3.141592654" xyz="-0.062 0.0045 0.012" />
        <axis xyz="0 0 1" />
        <limit effort="10.6" lower="-1.570796327" upper="1.570796327" velocity="3.14" />
        <mimic joint="gripper_joint" multiplier="1" />
        <dynamics damping="0.3" friction="0.0" /> 
    </joint>
    
    <link name="r_truss_arm_link">
        <collision>
            <origin rpy="0.0 0.0 0.0" xyz="0.016 -0.000 0.0045" />
            <geometry>
                <mesh filename="package://gripper_description/meshes/visual/RG3_grip_link_left_m.stl" />
            </geometry>
        </collision>
        <visual>
            <origin rpy="0.00 0.00 0.0" xyz="0.016 -0.000 0.0045" />
            <geometry>
                <mesh filename="package://gripper_description/meshes/visual/RG3_grip_link_left_m.stl" />
            </geometry>
        </visual>
        <inertial>
            <origin rpy="0.00 0.00 0.00" xyz="0.023075 -0.012136 -0.010000" />
            <mass value="0.0065927" />
            <inertia ixx="0.002" ixy="0.0" ixz="0.0" iyy="0.02" iyz="0.0" izz="0.002" />
        </inertial>
    </link>
    <joint name="r_finger_passive_joint" type="revolute">
        <parent link="palm_link" />
        <child link="r_truss_arm_link" />
        <origin rpy="0 0 3.141592654" xyz="-0.062 0.012 0.008" />
        <axis xyz="0 0 1" />
        <limit effort="10.6" lower="-1.570796327" upper="1.570796327" velocity="3.14" />
        <mimic joint="gripper_joint" multiplier="-1" />
        <dynamics damping="0.3" friction="0.0" />   
    </joint>
    
    <!-- Gazebo control plugins -->
    <gazebo>
        <plugin filename="libgazebo_ros_control.so" name="gazebo_ros_control">
            <robotNamespace>/</robotNamespace>
            <robotSimType>gazebo_ros_control/DefaultRobotHWSim</robotSimType>
        </plugin>
    </gazebo>
    <gazebo>
        <plugin filename="libroboticsgroup_gazebo_mimic_joint_plugin.so" name="r_finger_1_jointmimic_joint_plugin">
            <joint>gripper_joint</joint>
            <mimicJoint>r_finger_1_joint</mimicJoint>
            <multiplier>-1.0</multiplier>
            <offset>0</offset>
            <has_pid>false</has_pid>
            <sensitiveness>0.0</sensitiveness>
            <maxEffort>10.6</maxEffort>
        </plugin>
    </gazebo>
    <gazebo>
        <plugin filename="libroboticsgroup_gazebo_mimic_joint_plugin.so" name="l_finger_2_jointmimic_joint_plugin">
            <joint>gripper_joint</joint>
            <mimicJoint>l_finger_2_joint</mimicJoint>
            <multiplier>-1.0</multiplier>
            <offset>0</offset>
            <has_pid>false</has_pid>
            <sensitiveness>0.0</sensitiveness>
            <maxEffort>10.6</maxEffort>
        </plugin>
    </gazebo>
    <gazebo>
        <plugin filename="libroboticsgroup_gazebo_mimic_joint_plugin.so" name="r_finger_2_jointmimic_joint_plugin">
            <joint>gripper_joint</joint>
            <mimicJoint>r_finger_2_joint</mimicJoint>
            <multiplier>1.0</multiplier>
            <offset>0</offset>
            <sensitiveness>0.0</sensitiveness>
            <has_pid>false</has_pid>
            <maxEffort>10.6</maxEffort>
        </plugin>
    </gazebo>
    <gazebo>
        <plugin filename="libroboticsgroup_gazebo_mimic_joint_plugin.so" name="l_finger_passive_jointmimic_joint_plugin">
            <joint>gripper_joint</joint>
            <mimicJoint>l_finger_passive_joint</mimicJoint>
            <multiplier>1.0</multiplier>
            <offset>0</offset>
            <sensitiveness>0.0</sensitiveness>
            <has_pid>false</has_pid>
            <maxEffort>10.6</maxEffort>
        </plugin>
    </gazebo>
    <gazebo>
        <plugin filename="libroboticsgroup_gazebo_mimic_joint_plugin.so" name="r_finger_passive_jointmimic_joint_plugin">
            <joint>gripper_joint</joint>
            <mimicJoint>r_finger_passive_joint</mimicJoint>
            <multiplier>-1.0</multiplier>
            <offset>0</offset>
            <sensitiveness>0.0</sensitiveness>
            <has_pid>false</has_pid>
            <maxEffort>10.6</maxEffort>
        </plugin>
    </gazebo>
    <material name="Gazebo/Grey">
        <color rgba="0.8 0.8 0.8 1.0" />
    </material>
    <!-- Gazebo link properties -->
    <gazebo reference="link_base">
        <kp>1E12</kp>
        <kd>10</kd>
        <mu2>10.0</mu2>
        <material>Gazebo/Grey</material>
        <selfCollide>true</selfCollide>
    </gazebo>
    <gazebo reference="link_body">
        <kp>1E12</kp>
        <kd>10</kd>
        <mu1>10.0</mu1>
        <mu2>10.0</mu2>
        <material>Gazebo/Grey</material>
        <selfCollide>true</selfCollide>
    </gazebo>
    <gazebo reference="link_arm">
        <kp>1E12</kp>
        <kd>10</kd>
        <mu1>10.0</mu1>
        <mu2>10.0</mu2>
        <material>Gazebo/Grey</material>
        <selfCollide>true</selfCollide>
    </gazebo>
    <gazebo reference="link_forearm">
        <kp>1E12</kp>
        <kd>10</kd>
        <mu1>10.0</mu1>
        <mu2>10.0</mu2>
        <material>Gazebo/Grey</material>
        <selfCollide>true</selfCollide>
    </gazebo>
    <gazebo reference="hand_link">
        <mu1>0.2</mu1>
        <mu2>0.2</mu2>
        <material>Gazebo/White</material>
        <selfCollide>true</selfCollide>
    </gazebo>
    <gazebo reference="palm_link">
        <kp>1E12</kp>
        <kd>10</kd>
        <mu1>10.0</mu1>
        <mu2>10.0</mu2>
        <material>Gazebo/White</material>
        <selfCollide>false</selfCollide>
    </gazebo>
    <gazebo reference="l_moment_arm_link">
        <kp>1E12</kp>
        <kd>10</kd>
        <mu1>10</mu1>
        <mu2>10</mu2>
        <material>Gazebo/White</material>
        <selfCollide>false</selfCollide>
    </gazebo>
    <gazebo reference="r_moment_arm_link">
        <kp>1E12</kp>
        <kd>10</kd>
        <mu1>10</mu1>
        <mu2>10</mu2>
        <material>Gazebo/White</material>
        <selfCollide>false</selfCollide>
    </gazebo>
    <gazebo reference="l_finger">
        <kp>1E12</kp>
        <kd>10</kd>
        <mu1>10</mu1>
        <mu2>10</mu2>
        <material>Gazebo/White</material>
        <selfCollide>false</selfCollide>
    </gazebo>
    <gazebo reference="r_finger">
        <kp>1E12</kp>
        <kd>10</kd>
        <mu1>10</mu1>
        <mu2>10</mu2>
        <material>Gazebo/White</material>
        <selfCollide>false</selfCollide>
    </gazebo>
    <gazebo reference="l_truss_arm_link">
        <kp>1E12</kp>
        <kd>10</kd>
        <mu1>10</mu1>
        <mu2>10</mu2>
        <material>Gazebo/White</material>
        <selfCollide>false</selfCollide>
    </gazebo>
    <gazebo reference="r_truss_arm_link">
        <kp>1E12</kp>
        <kd>10</kd>
        <mu1>10</mu1>
        <mu2>10</mu2>
        <material>Gazebo/White</material>
        <selfCollide>false</selfCollide>
    </gazebo>
    

</robot>

